Workbook

Sheet MIL 科学注塑适用范围MIL Scientific Mold
A1: MIL 科学注塑适用范围 MIL Scientific Molding Applicable Scope
A2: 模具类型 Mold Tpye | B2: 温度设定 Temp. Setting | C2: 粘度曲线 Viscosity Curve | D2: 动态压力降 Dynamic Pressure Drop | E2: 型腔平衡 Cavity Balance | F2: 压力工艺窗口 Pressure Process Window | G2: 浇口冻结测试 gate freezingtest | H2: 锁模力优化 Optimization of clamping force
A3: Over mold（soft plastic） | D3: 选做 Optional
A4: 热流道模具 Hot Runner Mold | D4: 选做 Optional
A5: 1shot 胶量体积/注塑机总胶量≤20% The volume of 1shot /the total volume of the injection machine≤20% | D5: 选做 Optional
A6: 气辅模具 Gas-Assisted Mold | D6: 选做 Optional
A7: 单腔模具 Single Cavity Mold | D7: 选做 Optional
A8: 双色模 2K mold | D8: 选做 Optional
A10: 备注Note： 1.除表格模具类型以外的模具科学注塑需要做所有测试项 All test items need to be conducted for scientific injection molding of molds other than the mold types in the table. 2.双色模只做产品占比大的主胶位那一射 For 2K Molds, only the main shot (the shot with the larger product portion) is tested. 3.当做粘度测试时设置最佳速度时对应压力如果大于机台最大注塑压力的85%时则动态压力降测试必做项 低于机台最大注塑压力85%时动态压力测试 为选做项，适用所有模具 Applicable to all molds，When setting optimal speed for the Viscosity test, if the corresponding pressure exceeds 85% of the machine's maximum injection pressure, the Dynamic Pressure Drop test becomes mandatory. If below 85%, it remains optional.

Sheet MILScientific Injection Molding
A1: MIL Scientific Injection Molding Validation
A3: 产品信息（Part Information)
A4: Model No | B4: `018999001 | D4: 供应商 (Supplier) | G4: 负责人 Owner | J4: 试模日期 Shot data
A5: Part No | B5: Part Name | D5: Picture | F5: 产品理论重量 Part evaluate weight (g) | G5: 实际重量 part actual weight （g） | H5: 水口重量 gate weight (g) | I5: 理论总重量 (evaluate total weight) shot(g) | J5: 备注 Remark
A6: 370922001 | F6: 251 | H6: 20 | I6: =F6+F7+H6 -> 493
A7: 370923001 | F7: 222
A8: 模具信息(Tooling information)
A9: 模号(T/N) | B9: TG3A0004695-01 | D9: 流道形式 Runner type | E9: Sub gate | G9: CAV | H9: 1+1 | J9: 周期 cycle time （S） | K9: 55
A10: 材料信息(Material information)
A12: 品牌 Brand | B12: 型号(TYPE) | D12: 材料编号 Material number | F12: 颜色 color | H12: 密度 Density（g/cm） | J12: 试模前含水率 Moisture content before shot
A13: KING FA | B13: PA6+30GF%KA501 | F13: RED | H13: 1.35
A14: 推荐烘烤温度 Recommended Drying temperature(°C) | B14: 推荐烘烤时间 Drying Time(H) | D14: 推荐模温 Recommended Mold temperature(°C) | F14: 推荐料温 Recommended melt temperature(°C) | H14: 材料MFR Raw material MFR | J14: 产品MFR Part MFR
A16: 试模机台( Injection machine)
A18: 机台号 Machine number | B18: 品牌 Brand | C18: 类型 Machine type | D18: 吨位 Machine Size （Ton） | E18: 螺杆直径 Screw size) （mm） | F18: 最大注塑压力 Max injection pressure （Mpa） | G18: 最大液压压力 Max pump pressure （Bar） | I18: 最大射胶速度 Max injection speed mm/s | K18: 最大行程 Platen stroke （mm）
A19: 2# | B19: 海天 | C19: 油压机 | D19: 280 | E19: 60 | F19: 165 | G19: 165 | I19: 200 | K19: 200
A20: 增强比 Intensification Ratio | C20: 滞留时间 Retention time (min) | E20: 占总胶量百分比/shot （推荐大于20%并小于85%） Percentage of total volume /shot (Recommended to be more than 20% and less than 85%) | G20: MF推荐压力 MF recommend Pressure （Mpa） | I20: MF浇口冻结时间 MF gate freeze time （s） | K20: MF推荐冷却时间 MF recommended cooling time （s）
A21: =F19/G19*10 -> 10 | C21: =((E19^2/4)*3.14*K19/1000*H13)/I6/60*K9 -> 1.4187323 | E21: =I6/((E19^2/4)*3.14*K19*H13/1000)*1.15 -> 0.74303426
A22: 常用材料推荐滞留时间范围 The recommended retention time range for commonly used materials
A24: 常用材料名称 Material type | D24: 推荐最长滞留时间范围(min) The recommended maximum retention time range | G24: 说明 Instruction
A25: LDPE/HDPE（聚乙烯） | D25: 4~6 | G25: 耐热性较好，但过长停留可能导致氧化降解。 It has good heat resistance, but excessive retention may lead to oxidative degradation
A26: PP（聚丙烯） | D26: 4~6 | G26: 类似PE，需避免高温下长时间停留。 Similar to PE, it is necessary to avoid staying at high temperatures for a long time.
A27: ABS（丙烯腈丁二烯苯乙烯） | D27: 5~8 | G27: 耐热性较好，但苯乙烯组分可能挥发，影响性能。 It has good heat resistance, but the styrene component may volatilize, affecting its performance.
A28: PC（聚碳酸酯） | D28: 6~10 | G28: 高温下易水解，需预干燥，停留时间可稍长。 It is prone to hydrolysis at high temperatures and requires pre-drying. The retention time can be slightly longer.
A29: PA6/PA66（尼龙） | D29: 4~8 | G29: 吸湿性强，需干燥；高温下可能降解，时间不宜过长。 It has strong hygroscopicity and requires drying. It may degrade at high temperatures, but the time should not be too long.
A30: POM（聚甲醛） | D30: 4~7 | G30: 对过热敏感，易分解产生甲醛气体，需精确控制。 It is sensitive to overheating and prone to decomposition to produce formaldehyde gas, which requires precise control.
A31: PET（聚酯） | D31: 3~5 | G31: 易水解，需充分干燥；停留过长易导致粘度下降和降解。 It is prone to hydrolysis and requires thorough drying. Staying for too long can easily lead to a decrease in viscosity and degradation.
A32: PBT（聚对苯二甲酸丁二醇酯） | D32: 3~5 | G32: 类似PET，需快速加工避免降解。 Similar to PET, it needs to be processed quickly to avoid degradation.
A33: TPU（热塑性聚氨酯） | D33: 3~6 | G33: 黏度高，停留过长可能导致交联或变色。 High viscosity. Prolonged residence may lead to cross-linking or discoloration.
A34: PMMA（亚克力） | D34: 4~7 | G34: 透明性要求高，需避免热分解导致的雾化。 High transparency is required, and fogging caused by thermal decomposition needs to be avoided
A35: PEEK（聚醚醚酮） | D35: 10~15 | G35: 耐高温性能优异，允许较长停留时间，但需避免局部过热。 It has excellent high-temperature resistance and allows for a longer residence time, but local overheating should be avoided.
A36: 流程图 flow diagram
A44: 测试总结
A45: 推荐填充速度 Recommended fill speed | C45: 峰值压力占机台 最大压力% Peak pressure accounts for the machine Maximum pressure | D45: 型腔平衡 CAV balance (OK or NG) | E45: 推荐保压压力 Recommended Hold pressure | G45: 推荐保压时间 Recommended Hold time | I45: 推荐锁模力 Recommended Clamping Force | K45: 备注 Remark
A46: 百分比(Percent) | B46: mm/s | E46: ='动态压力降测试Dynamic pressure test'!D20 -> Bar | G46: S | I46: ='锁模力优化Optimization of clamping f'!C16 -> Bar
A47: ='粘度曲线Viscosity Curve'!B40 -> 70%~90% | B47: ='粘度曲线Viscosity Curve'!C40 -> 72~109 | C47: ='动态压力降测试Dynamic pressure test'!D40 -> 0.96969697 | D47: ='型腔平衡测试CAV balance test'!N43 -> OK | E47: ='压力工艺窗口Pressure process window'!D22 -> 30 | G47: ='浇口冻结测试Gate freezing test'!C34 -> 11 | I47: ='锁模力优化Optimization of clamping f'!G40 -> 200
D48: 批准Approved： | H48: 日期Date：

Sheet 温度设置 Set Temp
A1: 温度设置 Temperature set
A3: 热流道温控箱（°C） Hot runner temperature control box | I3: 炮台温度(°C) Barrel Temp
A4: N/A | B4: N/A | C4: N/A | D4: N/A | E4: N/A | F4: N/A | G4: N/A | H4: N/A
I5: 射咀 Nozzle | K5: 第一段 Zone1 | M5: 第二段 Zone2 | N5: 第三段 ZOne3 | O5: 第四段 Zone4 | P5: 第五段 Zone5
I6: 255 | K6: 265 | M6: 265 | N6: 261 | O6: 255 | P6: 245
A7: 前模温度CAV Temp
A8: 设置温度°C Set Temp °C | E8: 运水链接方式 Cooling In/Out
A9: 60 | E9: Example:（in 1==>out 1==> in 2==> ）
A11: 60
A13: N/A
A15: 后模温度COR Temp
A16: 设置温度°C Set Temp °C | E16: 运水链接方式 Cooling In/Out
A17: 14 | E17: Example（in 1==>out 1==> in 2==> ）
A18: 14
A19: 14
A20: 行位/其他 Slide/other
A21: 设置温度°C Set Temp °C | E21: 运水链接方式 Cooling In/Out
A22: Slider 1 | C22: 60
A23: Slider 2 | C23: 60
A24: Slider 3 | C24: N/A
A25: Slider 4 | C25: N/A
A26: Slider 5 | C26: N/A
A27: Slider 6 | C27: N/A
A28: 前模实际模温(°C) Act. Temp of the CAV side(°C) | I28: 后模实际模温(°C) Act. Temp of the COR side(°C)

Sheet 粘度曲线Viscosity Curve
A1: 粘度曲线 Viscosity Curve
A3: 目的（PURPOSE） 找到最佳射胶速度 Find the optimal injection speed. 试验方法（PROCEDURE） 1.只设置一段填充，关闭保压压力和保压时间 Only set one stage of filling, and close the holding pressure and holding time. 2.设置高压高速，调整螺杆位置找到产品外形90%-95%的状态 Set high pressure and high speed, and adjust the position of the screw to reach 90%-95% of the fill. 3.从高速至低速开始测试。 Start the test from high speed to low speed. 4.从高速到低速记录填充峰值压力和填充时间 Record the peak filling pressure and filling time from high speed to low speed. 5.计算剪切速率和有效粘度（自动） Calculate shear rate and effective viscosity (Automatic) 6.绘制粘度曲线（自动） Draw viscosity curve (Automatic). 7.选择有效粘度曲线图中有效粘度趋于平缓区域对应的剪切速率，根据最佳剪切速率区间从而选出最佳射胶速度区间。 Select the shear rate corresponding to the area where the effective viscosity tends to be flat in the effective viscosity curve graph, and then select the optimal injection speed range based on the optimal shear rate range
A12: 有效粘度 Effective Viscosity
A13: 填充速度 Fill speed | D13: 切换位置 Switch position | E13: 填充时间 Fill time | F13: 注塑峰值压力 Injection peak pressure | G13: 剪切率 Shear rate | H13: 有效粘度 Effective Viscosity
A15: 百分比 Percent | C15: mm/sec | D15: mm | E15: sec | F15: Mpa | G15: 1/t | H15: MPa*s
A16: 0.9 | C16: 79 | D16: 35 | E16: 2.35 | F16: 164 | G16: =1/E16 -> 0.42553191 | H16: =E16*F16 -> 385.4
A17: 0.8 | C17: 70 | D17: 35 | E17: 2.6 | F17: 155 | G17: =1/E17 -> 0.38461538 | H17: =E17*F17 -> 403
A18: 0.7 | C18: 62 | D18: 35 | E18: 2.69 | F18: 150 | G18: =1/E18 -> 0.37174721 | H18: =E18*F18 -> 403.5
A19: 0.6 | C19: 52 | D19: 35 | E19: 3.25 | F19: 142 | G19: =1/E19 -> 0.30769231 | H19: =E19*F19 -> 461.5
A20: 0.5 | C20: 42 | D20: 35 | E20: 3.85 | F20: 133 | G20: =1/E20 -> 0.25974026 | H20: =E20*F20 -> 512.05
A21: 0.3 | C21: 26 | D21: 35 | E21: 6.2 | F21: 111 | G21: =1/E21 -> 0.16129032 | H21: =E21*F21 -> 688.2
A22: 0.1 | C22: 9.7 | D22: 35 | E22: 22.63 | F22: 95 | G22: =1/E22 -> 0.044189129 | H22: =E22*F22 -> 2149.85
B38: 推荐注塑速度 Recommended injection speed
B39: 百分比 Percent | C39: mm/s
B40: 70%~90% | C40: 72~109

Sheet 动态压力降测试Dynamic pressure  test
A1: 动态压力降测试Dynamic pressure test
A3: 目的（PURPOSE） 确定在填充过程中注射压力的损失情况。 Determine the loss of injection pressure during the filling process. 试验方法（PROCEDURE) 1.只设置一段填充，关闭保压压力和保压时间。 Only set one stage of filling, and close the holding pressure and holding time. 2.设置根据粘度曲线找到的最佳射胶速度为填充速度。 Set the optimal injection speed found based on the viscosity curve as the filling speed 3.后退炮台空射，记录压力峰值。 Withdraw the nozzle for empty shooting and record the peak pressure. 4.调整射胶位置，使熔胶刚好填充满主流道，记录压力峰值 Adjust the injection position, just fill the main runner, and record the peak pressure 5.调整射胶位置，使熔胶填充主流道和分流道，记录压力峰值 Adjust the injection position to fill the main runner and the distribution runner, and record the peak pressure 6.调整射胶位置，使熔胶刚好通过进浇口，记录压力峰值 Adjust the injection position, just passe through the gate, and record the peak pressure 7.调整射胶位置，使熔胶填满型腔50%，记录压力峰值 Adjust the injection position to fill 50% of the cavity, and record the peak pressure 8.调整射胶位置，使熔胶填满型腔99%，记录压力峰值 Adjust the injection position to fill 99% of the cavity, and record the peak pressure 9.绘制压力损失图，分析压力损失是否合理（自动） Draw the pressure loss graph and analyze whether the pressure loss is reasonable (Automatic)
B20: 压力单位(Pressure unit) | D20: Bar
D21: 序号 Number | E21: 流动截面 Flow section | F21: 峰值压力 Peak pressure
D22: 1 | E22: 喷咀Nozzle | F22: N/A
D23: 2 | E23: 流道Runner | F23: 49
D24: 3 | E24: 浇口Gate | F24: 63
D25: 4 | E25: 50%产品 fill 50% part | F25: 151
D26: 5 | E26: 产品V/P V/P part | F26: 160
A40: 填充V/P位置 的压力 V/P pressure | B40: =F26 -> 160 | C40: 峰值压力占机台最大压力% Peak pressure accounts for the machine Maximum pressure | D40: =B40/'MILScientific Injection Molding'!G19 -> 0.96969697
A41: 备注：动态压力降测试属于选做项 填充到产品体积99%，推荐达到粘度曲线找到的填充速度所需的填充压力不超过机台最大压力的85% Note: The dynamic pressure test is an optional item. Fill up to 99% of the product volume. It is recommended that the filling pressure required to reach the filling speed found by the viscosity curve does not exceed 85% of the maximum pressure of the machine

Sheet 型腔平衡测试CAV balance test
A1: 型腔平衡测试 CAV balance test
A3: 多腔同一产品模具 Multi-cavities mold for the same product
A4: 目的（PURPOSE） 确认多型腔模具的平衡性 Confirm the balance of the multi-cavities mold 试验方法（PROCEDURE) 1.只设定一段填充，关掉保压压力和时间 Only set one stage of filling, and close the holding pressure and holding time. 2.设置根据粘度曲线找到的最佳射胶速度为填充速度。 Set the optimal injection speed found based on the viscosity curve as the filling speed. 3.待注塑稳定后分别注塑一模短射20%~70%和VP位置的零件，称重每个零件的重量计算3pcs平均重量。 After the injection molding is stable, inject 20% to 70% of the parts and those at the VP position in one mold respectively. Weigh the weight of each part and calculate the average weight of 3 pcs.. 4.计算不平衡程度（自动） Calculate the degree of imbalance (Automatic) 5.当产品重量≤1g,普通称无法满足称重精度，建议用目视判断型腔平衡。 When the product weight is ≤1g, it cannot meet the weighing accuracy requirements. It is recommended to visually judge the balance of the cavity.
A11: 短射产品体积20%~70% The volume of short-shot products is 20% to 70% | J11: 短射产品VP位置 The VP position of short-shot products
A12: 型腔# Cav# | B12: 照片 Picture | C12: shot1 （g） | D12: shot2 （g） | E12: shot3 （g） | F12: 平均重量 Ave weight （g） | J12: 型腔# Cav # | K12: 照片 Picture | L12: shot1 （g） | M12: shot2 （g） | N12: shot3 （g） | O12: 平均重量 Ave weight （g）
A13: 1 | B13: 1shot 短射照片 （必填） | C13: 25 | D13: 25 | E13: 24.5 | F13: =AVERAGE(C13:E13) -> 24.833333 | J13: 1 | K13: 1shot 短射照片 （必填） | L13: 47.5 | M13: 47.2 | N13: 47.5 | O13: =AVERAGE(L13:N13) -> 47.4
A14: 2 | C14: 25.3 | D14: 25.2 | E14: 25.1 | F14: =AVERAGE(C14:E14) -> 25.2 | J14: 2 | L14: 42 | M14: 42 | N14: 42 | O14: =AVERAGE(L14:N14) -> 42
A15: 3 | C15: 25.8 | D15: 26 | E15: 25.5 | F15: =AVERAGE(C15:E15) -> 25.766667 | J15: 3 | L15: 47.5 | M15: 47.2 | N15: 47.5 | O15: =AVERAGE(L15:N15) -> 47.4
A16: 4 | C16: 24.9 | D16: 24.5 | E16: 24.8 | F16: =AVERAGE(C16:E16) -> 24.733333 | J16: 4 | L16: N/A | M16: N/A | N16: N/A | O16: =AVERAGE(L16:N16) -> #DIV/0!
A17: 5 | C17: 25.3 | D17: 25.2 | E17: 25.5 | F17: =AVERAGE(C17:E17) -> 25.333333 | J17: 5 | L17: N/A | M17: N/A | N17: N/A | O17: =AVERAGE(L17:N17) -> #DIV/0!
A18: 6 | C18: 24.6 | D18: 24.8 | E18: 25 | F18: =AVERAGE(C18:E18) -> 24.8 | J18: 6 | L18: N/A | M18: N/A | N18: N/A | O18: =AVERAGE(L18:N18) -> #DIV/0!
A19: 7 | C19: 24.9 | D19: 24.5 | E19: 24.6 | F19: =AVERAGE(C19:E19) -> 24.666667 | J19: 7 | L19: N/A | M19: N/A | N19: N/A | O19: =AVERAGE(L19:N19) -> #DIV/0!
A20: 8 | C20: 25.5 | D20: 25.2 | E20: 25.4 | F20: =AVERAGE(C20:E20) -> 25.366667 | J20: 8 | L20: N/A | M20: N/A | N20: N/A | O20: =AVERAGE(L20:N20) -> #DIV/0!
A21: 最大值： Min value | B21: =MAX(F13:F20) -> 25.766667 | J21: 最大值： Min value | K21: =MAX(O13:O20) -> #DIV/0!
A22: 最小值： Min Value | B22: =MIN(F13:F20) -> 24.666667 | J22: 最小值： Min value | K22: =MIN(O13:O20) -> #DIV/0!
A23: 不平衡程度 Degree of imbalance | B23: =(B21-B22)/B21 -> 0.042690815 | J23: 不平衡程度 Degree of imbalance | K23: =(K21-K22)/K21 -> #DIV/0!
A24: 推荐判定标准：小于或等于3% 为OK. Recommended judgment criterion: less than or equal to 3% is considered OK.
A25: 家族模具 Family mold
A26: 目的 （PURPOSE） 确认多型腔模具的平衡性 Confirm the balance of the multi-cavities mold 试验方法（PROCEDURE) 1.只设定一段填充，关掉保压压力和时间 Only set one stage of filling, and close the holding pressure and holding time. 2.设置根据粘度曲线找到的最佳射胶速度为填充速度。 Set the optimal injection speed found based on the viscosity curve as the filling speed. 3.待注塑稳定后分别注塑一模短射20%~70%和VP位置的零件，称重每个零件的重量计算3pcs平均重量。 3. After the injection molding is stable, inject 20%~70% of the parts and those at the VP position in one mold respectively. Weigh the weight of each part and calculate the average weight of 3 pcs. 4.计算不平衡程度（自动） Calculate the degree of imbalance (Automatic) 5.如果目视平衡结果与重量占总量百分比平衡偏差比较大以目视平衡为准 If the visual balance result deviates significantly from the weight as a percentage of the total weight, the visual balance shall prevail | O26: 理论重量（g）
N27: part1 | O27: ='MILScientific Injection Molding'!F6 -> 251
N28: part2 | O28: ='MILScientific Injection Molding'!F7 -> 222
N29: part3 | O29: N/A
N30: part4 | O30: N/A
A35: 短射产品体积20%~70% The volume of short-shot products is 20% to 70% | I35: 短射产品VP位置 The VP position of short-shot products
A36: 型腔# Cav# | B36: 照片 Picture | C36: shot （g） | D36: shot （g） | E36: shot （g） | F36: 平均值 Ave（g） | G36: 占理论总重量百分比 Percentage of the theoretical total weight | I36: 型腔# | J36: 照片 Picture | K36: shot （g） | L36: shot （g） | M36: shot （g） | N36: 平均值 Ave （g） | O36: 占理论总重量百分比 Percentage of the theoretical total weight
A37: Part1 | B37: 1shot 短射照片 （必填） | C37: 111.2 | D37: 111.2 | E37: 111.3 | F37: =AVERAGE(C37:E37) -> 111.23333 | G37: =F37/O27 -> 0.44316069 | I37: Part1 | J37: 1shot 短射照片 必填 | K37: 231.2 | L37: 231.4 | M37: 231.6 | N37: =AVERAGE(K37:M37) -> 231.4 | O37: =N37/O27 -> 0.92191235
A38: Part2 | C38: 94 | D38: 93.9 | E38: 94.1 | F38: =AVERAGE(C38:E38) -> 94 | G38: =F38/O28 -> 0.42342342 | I38: Part2 | K38: 202 | L38: 202 | M38: 202 | N38: =AVERAGE(K38:M38) -> 202 | O38: =N38/O28 -> 0.90990991
A39: Part3 | C39: 0 | D39: 0 | E39: 0 | F39: =AVERAGE(C39:E39) -> 0 | G39: N/A | I39: Part3 | K39: 0 | L39: 0 | M39: 0 | N39: =AVERAGE(K39:M39) -> 0 | O39: N/A
A40: Part4 | C40: 0 | D40: 0 | E40: 0 | F40: =AVERAGE(C40:E40) -> 0 | G40: N/A | I40: Part4 | K40: 0 | L40: 0 | M40: 0 | N40: 0 | O40: N/A
A41: 偏差 Deviation | B41: =MAX(G37:G40)-MIN(G37:G40) -> 0.019737267 | I41: 偏差 Deviation | J41: =MAX(O37:O40)-MIN(O37:O40) -> 0.012002441
A42: 推荐判定标准：小于或等于3% 为OK, 当大于3% 时需要目视判断是否OK Recommended judgment criterion: less than or equal to 3% is considered OK.
K43: 结果判定 Result determination | N43: OK

Sheet 压力工艺窗口Pressure process window
A1: 压力工艺窗口 Pressure process window
A3: 目的（PURPOSE） 找到最佳保压压力 Find the optimal pressure-holding pressure. 试验方法(（PROCEDURE) 1.调整合适的锁模力 Adjust the appropriate clamping force. 2.只射定一段填充，设置根据粘度曲线找到的最佳射胶速度为填充速度，并调整填充位置到VP位置。 Only set one stage of filling, the optimal injection speed found based on the viscosity curve is set as the filling speed and adjust the position of the screw to the V/P. 3.设置尽可能长的保压时间（大于浇口冻结时间） Set the holding pressure time as long as possible (longer than the gate freezing time). 4.保压压力从低到高分别记录产品重量并观察外观情况直到产品PL披风 Record the weight of the products from low to high holding pressure and observe the appearance until the flash is appearing. 5.找到产品外观合格最低压力和最高压力窗口. Find the minimum and maximum pressure Windows for the qualified appearance of the product 7.取最低压力和最高压力中值为最佳保压压力 Take the median of the lowest pressure and the highest pressure as the optimal holding pressure 8.默认不需要添加产品外观照片，根据客户需求特殊case需要添加照片 By default, product appearance photos are not required to be included unless specifically requested by customers for special cases.
B11: 保压压力(Bar) holding pressure | C11: 保压时间(s) holding time | D11: 产品重量(g) Part weight | E11: 产品外观 part appearance | F11: 照片 Picture
B12: 10 | C12: 12 | D12: 465 | E12: 产品缩水 shrink | F12: 选填
B13: 20 | C13: 12 | D13: 471.2 | E13: 产品OK | F13: 选填
B14: 30 | C14: 12 | D14: 474.8 | E14: 产品OK | F14: 选填
B15: 35 | C15: 12 | D15: 477.6 | E15: 产品OK | F15: 选填
B16: 40 | C16: 12 | D16: 479.5 | E16: 产品披风 flash | F16: 选填
B17: N/A | C17: N/A | D17: N/A | E17: N/A | F17: 选填
B18: N/A | C18: N/A | D18: N/A | E18: N/A | F18: 选填
B19: N/A | C19: N/A | D19: N/A | E19: N/A | F19: 选填
B21: 最小压力(Bar) Min pressure | C21: 最大压力(Bar) Max pressure | D21: 推荐压力(Bar) recommended pressure
B22: 20 | C22: 40 | D22: =(C22+B22)/2 -> 30

Sheet 浇口冻结测试Gate freezing test
A1: 浇口冻结Gate freezing test
A3: 目的（PURPOSE） 确认浇口冻结时间，确认保压时间 Confirm the freezing time of the gate and the holding pressure time 试验方法(（PROCEDURE) 1.调整合适的锁模力。 Adjust the appropriate clamping force. 2.只射定一段填充，设置根据粘度曲线找到的最佳射胶速度为填充速度，并调整填充位置到VP位置。 Only set one stage of filling, the optimal injection speed found based on the viscosity curve is set as the filling speed and adjust the position of the screw to the V/P. 3. 只设定一段保压，设置根据压力测试得出的最佳保压压力。 Only set one stage of holding pressure and set the optimal holding pressure obtained based on the pressure test. 4.从低到高设置保压时间分别记录产品重量。 Set the holding pressure time from low to high and record the product weight respectively. 5.当产品重量不再增加时对应的时间为浇口冻结时间。 The time corresponding to when the product weight no longer increases is the gate freezing time 6.以下类型模具选择产品重量增加缓慢时对应的时间为保压时间。 For the following types of molds, the holding pressure time is determined as the time point at which the product mass increment exhibits a significant rate reduction. a) 注塑材料流动性非常好（如TPE，TPU等）浇口无法短时间冻结。 Molds using injection materials with high fluidity (e.g., TPE, TPU), where the gate cannot freeze within a short time. b)热流道模具，直接浇口模具，浇口无法短时间冻结或无法冻结 Hot-runner molds or direct-gate molds, where the gate either fails to solidify within a short time or remains unfrozen entirely.
A20: 模次 shot | B20: 保压时间 holding time(s) | C20: 零件重量 Part weight(g)
A21: 1 | B21: 3 | C21: 447
A22: 2 | B22: 4 | C22: 449
A23: 3 | B23: 5 | C23: 450
A24: 4 | B24: 6 | C24: 451.9
A25: 5 | B25: 7 | C25: 452.7
A26: 6 | B26: 8 | C26: 453.7
A27: 7 | B27: 9 | C27: 454.6
A28: 8 | B28: 10 | C28: 455
A29: 9 | B29: 11 | C29: 456
A30: 10 | B30: 12 | C30: 456
A33: 浇口冻结时间 gate freexing time(S) | C33: 10
A34: 推荐保压时间 recommended holding pressure time（S） | C34: =C33+1 -> 11

Sheet 锁模力优化Optimization of clamping f
A1: 锁模力优化Optimization of clamping force
A3: 目的（PURPOSE） 找到最佳锁模力 Find the optimal clamping force 试验方法(（PROCEDURE) 1.只射定一段填充，设置根据粘度曲线找到的最佳射胶速度为填充速度，并调整填充位置到VP位置。 Only set one stage of filling, the optimal injection speed found based on the viscosity curve is set as the filling speed and adjust the position of the screw to the V/P. 2. 只设置一段保压，设置根据压力工艺窗口测试得出的最佳保压压力. Only set one stage of holding pressure,and the optimal holding pressure is determined based on the pressure process window test. 3.设置根据浇口冻结测试找到的最佳保压时间 Set the optimal holding pressure time found based on the gate freezing test 4.不断降低锁模力分别称重记录并检查产品外观 Continuously reduce the clamping force, weigh and record respectively, and inspect the appearance of the product 4.直到产品重量发生变化并检查PL面是否产生披风 Until the product weight changes and check if appear flash on the PL surface 5.默认不需要添加产品外观照片，根据客户需求特殊case需要添加照片 By default, product appearance photos are not required to be included unless specifically requested by customers for special cases.
A16: 压力单位 Pressure unit | C16: Bar
C17: 模次 shot | D17: 锁模力 clamping force | E17: 产品重量 Part weight （g） | F17: 产品外观（是否有披风) Part appearance | G17: 照片 Picture
C18: 1 | D18: 160 | E18: 305 | F18: 外观OK | G18: 选填
C19: 2 | D19: 140 | E19: 305 | F19: 外观OK | G19: 选填
C20: 3 | D20: 130 | E20: 305 | F20: 外观OK | G20: 选填
C21: 4 | D21: 120 | E21: 305 | F21: 外观OK | G21: 选填
C22: 5 | D22: 110 | E22: 306 | F22: 产品有披风 | G22: 选填
C23: 6 | D23: 100 | E23: 308 | F23: 产品有披风 | G23: 选填
C40: 合模最大液压压力 Maximum hydraulic pressure for mold closing | D40: 140 | F40: 推荐锁模力(Ton) Recommended clamping force | G40: 200

Sheet MIL INJECTION MOLD TRIAL SHOT R
A1: MIL INJECTION MOLD TRIAL SHOT RECORD 试模参数记录表
A2: Moldel No.: | D2: ='MILScientific Injection Molding'!B4 -> `018999001 | G2: Mold maker: | M2: Date: | Q2: 记录编号: | R2: T
A3: M/C Set Up | B3: Part No. 产品编号 | G3: Part Name 产品名称 | M3: Tooling No. 模具编号 | N3: ='MILScientific Injection Molding'!B9 -> TG3A0004695-01
B4: Machine brand 啤机品牌 | C4: ='MILScientific Injection Molding'!B19 -> 海天 | E4: machine Type 机器类型 (油机/电机) | F4: ='MILScientific Injection Molding'!C19 -> 油压机 | G4: Machine Size 啤机吨位 | H4: ='MILScientific Injection Molding'!D19 -> 280 | I4: Screw Diameter 螺杆直径(mm) | K4: ='MILScientific Injection Molding'!E19 -> 60 | M4: Max injection pressure 啤机最大注射压力 | N4: ='MILScientific Injection Molding'!F19 -> 165 | O4: Mpa | P4: Intensification Ratio 啤机增强比 | Q4: Max Injection Speed 最大 注射速度 | R4: ='MILScientific Injection Molding'!I19 -> 200 | S4: MM/S
B5: Material 塑料材料 | C5: ='MILScientific Injection Molding'!B13 -> PA6+30GF%KA501 | E5: Color 颜 色 | F5: ='MILScientific Injection Molding'!F13 -> RED | G5: Regrind rate (水口比例) | I5: Drying Temperature 烤料温度 | K5: Time (H) 烤料时间 | M5: Max system pressure 啤机最大系统压力 | N5: ='MILScientific Injection Molding'!G19 -> 165 | O5: Bar | P5: =N4*10/N5 -> 10
B6: MoldSize(L*W*H) 模具尺寸（ mm ） | G6: Cavity Qty (模穴数) | H6: ='MILScientific Injection Molding'!H9 -> 1+1 | I6: Core Pulling 缩呵 | K6: Hydraulic 抽呵 | M6: Limit Switch (限位制) | O6: Other dry Treatment (特殊处理) | Q6: Clamping Force 锁模力 | S6: Bar
B7: Core Pull Sequence (抽芯顺序) | S7: KN
A8: Molding Condition | B8: Cylinder Temp.℃ 炮筒温度℃ | D8: Nozzle℃ 炉嘴温度℃ | E8: ='温度设置 Set Temp'!I6 -> 255 | G8: 1st Stage℃ 一段温度℃ | H8: ='温度设置 Set Temp'!K6 -> 265 | I8: ℃ | J8: 2nd Stage℃ 二段温度℃ | K8: ='温度设置 Set Temp'!M6 -> 265 | L8: ℃ | M8: 3rd Stage℃ 三段温度℃ | N8: ='温度设置 Set Temp'!N6 -> 261 | P8: 4th Stage℃ 四段温度℃ | Q8: ='温度设置 Set Temp'!O6 -> 255
B9: Inj. Pressure 射胶 | D9: 1st Stage 一段 | E9: 2nd stage 二段 | F9: 3rd stage 三段 | G9: 4th Stage 四段 | H9: 5th Stage 五段 | I9: Total Inj. Time(s) 射胶时间(s) | J9: VP position VP 切换位置 | K9: Hold Pressure 保压 | M9: 1st Stage 一段 | N9: 2nd stage 二段 | O9: 3rd stage 三段 | P9: 4th Stage 四段 | Q9: 5th Stage 五段 | R9: Total Hold time (s) 总保压时间 (s)
B10: Inj. Pressure 射胶压力 | C10: Bar | K10: Hold Pressure 保压压力 | L10: Bar | M10: 40 | N10: 70 | R10: =L14+M14+N14+O14+P14+Q14 -> 10
C11: Mpa | L11: Mpa
B12: Inj. Speed 射胶速度 | C12: % | J12: VP time VP 切换时间 | K12: Hold Speed 保压速度 | L12: % | M12: 3 | N12: 4
C13: MM/S | L13: MM/S
B14: Inj.Position 射胶位置 | K14: Hold time (s) 保压时间 (s) | M14: 1 | N14: 9
B15: Melt pressure 熔胶压力 | C15: Bar | E15: Melt Speed 熔胶速度 | F15: % | H15: backpressure 背压压力 | I15: Bar | K15: PLASTIC.STORE 熔胶终点 | L15: 150 | M15: mm | N15: Screw retraction 松退 | P15: mm | Q15: Cushion 残胶量 | S15: mm
C16: Mpa | F16: MM/S | I16: Mpa
B17: Cooling System setting 冷却系统设定 | C17: Front Mold and Slides Cooling lines 前模/行位 | E17: ℃ | F17: 如（in 1==> in 2==> ) | J17: ℃ | K17: 140 | O17: ℃
E18: ℃ | J18: ℃ | O18: ℃
E19: ℃ | J19: ℃ | O19: ℃
C20: Front Mold and Slides Cooling lines 后模/行位 | E20: ℃ | J20: ℃ | O20: ℃
E21: ℃ | J21: ℃ | O21: ℃
E22: ℃ | J22: ℃ | O22: ℃
B23: Cavity Temp.℃ 实测前模温度℃ | C23: High 最高温度 | D23: Low 最低温度 | E23: Core Temp.℃ 实测后模温度℃ | F23: High 最高温度 | G23: Low 最低温度 | H23: Slide Temp.℃ 实测行位温度℃ | I23: High 最高温度 | J23: Low 最低温度 | K23: Other℃ 其它(实测) | L23: High 最高温度 | M23: Low 最低温度 | N23: Cooling Time(s) 冷却时间 (s) | Q23: Cycle Time 周期时间 (s)
B25: Hot runner Temp.℃ 热流道温度 ℃ | D25: GATE 1 浇口1 | F25: GATE 2 浇口2 | H25: GATE 3 浇口3 | J25: GATE 4 浇口4 | L25: GATE 5 浇口5 | N25: GATE 6 浇口6 | P25: GATE 7 浇口7 | R25: GATE 8 浇口8
B27: Needle valve time controller 针阀时间控制器 | D27: DELAY 延迟 | E27: OPEN 打开 | F27: DELAY 延迟 | G27: OPEN 打开 | H27: DELAY 延迟 | I27: OPEN 打开 | J27: DELAY 延迟 | K27: OPEN 打开 | L27: DELAY 延迟 | M27: OPEN 打开 | N27: DELAY 延迟 | O27: OPEN 打开 | P27: DELAY 延迟 | Q27: OPEN 打开 | R27: DELAY 延迟 | S27: OPEN 打开
B29: Ejection 顶 出 | D29: automatic 自动 | F29: semiautomatic 半自动 | H29: other 其它 | K29: Operator (操作人数) | N29: Rework 后加工
A30: Tooling & Sample Condition | B30: Sample QTY 样办数量 (啤) | H30: Part Wt. 产品重量 g/pcs | L30: Runner Wt 水口重量 g/啤 | P30: Shrinkage 缩水数
B31: Cosmetic (外观) | D31: Short Shot 缺料 | H31: Flash 批锋 | L31: Dark Spots 黑点 | P31: Poor Venting (排气不良)
D32: Sink Marks 缩水 | H32: Flow Marks 流纹 | L32: Burn Marks 烧胶 | P32: Moisture 气纹
D33: Scratch 拖伤 | H33: Sticking in Cav(粘前模) | L33: White Marks 顶白 | P33: Poor Polishing 省模不够
D34: Weld Line 熔接线 | H34: sticking in Core 粘后模 | L34: Crack 裂缝 | P34: Deformation (变形)
D35: Cavity Marking 模号标示 | H35: Mterial mark 材料标识 | L35: P/N mark 产品编号标识 | P35: Not balanced injection flow. 走胶不平衡
B36: Tooling performance 模具动作 | D36: Guide pin move smoothly? 导柱是否顺畅? | H36: Ejector move smoothly? 顶针是否顺畅? | L36: Cooling water leakage? 运水是否泄露? | P36: Is the mold temperature average? 模具温度是否平均
B37: Other Defect description (其他模具缺陷描述)
A38: Production condition | B38: Tooling structure & performance 模具结构和动作: | D38: Accept | I38: RejectComments:
B39: Quality of parts 产品质量 | D39: Accept | I39: RejectComments:
B40: Jig Fixture: | L40: STD M/C : Ton | P40: Act. M/C:Ton
A41: Remark: 1. 新project试模, 水口比例应与生产状态标准比例相同. 2. 产品重量需要去除五金或其他insert 的重量, 硬/软胶重量分开 3. 产品重量，水口重量严格遵从实际样板重量（精确到小数点后一位）. 4. 周期/顿位超Spec: 提供详细解释说明+不同参数的样板评估确认. 5:油机压力单位为bar /电机压力单位为MPa) 1Bar≈14.5psi=0.1MPa 6.油机速度单位为%/电机速度单位为mm/s | L41: STD Cycle: Sec. | P41: Act. Cycle:Sec.
L42: Tooling Vendor | P42: TTI Tooling Group
L43: Prepared By: | P43: Prepared By:
...

Sheet Standard curve of the sensor
A1: 传感器基准曲线 Sensor Baseline‌ Curve
A3: Sensor Baseline‌ Curve
A27: Sensor location
A48: 结果判定：Sensor曲线正常，压力合理，连续注塑曲线波动在5%以内 Result determination: The Sensor curve is normal, the pressure is reasonable, and the fluctuation of the continuous injection molding curve is within 5%
